Workbook

Sheet Tables
A1: Supplementary material to A Three-Decision Framework for Explicit Adjustment in Composite Indices: Integrating Aggregation, Multidimensional Balance, and Policy Diagnosis
A3: Table S1 Raw and normalized selected OECD health indicators | K3: Table S2 Baseline composite scores, coefficient of variation, and retention factors for λ=1 | T3: Table S3 Arithmetic-mean adjusted indices for OECD health indicators
A4: Country | B4: x1 | C4: x2 | D4: x3 | E4: x4 | F4: Normalized 70 to 130 | K4: Baseline operators | O4: Retention factor | T4: Arithmetic Adjusted Composite Index | X4: Hierarchy
B5: Lexp (benefit) | C5: Mortality (cost) | D5: Doctors (benefit) | E5: Beds (benefit) | F5: z1 | G5: z2(Rev) | H5: z3 | I5: z4 | K5: A | L5: G | M5: T | N5: CV | O5: Linear L= 1-CV | P5: Quadratic Q= 1-CV^2 | Q5: Rreciprocal R= 1/(1+CV) | R5: Exponential E= exp(-CV) | T5: AL | U5: AQ | V5: AR | W5: AE | X5: Rank AL | Y5: Rank AQ | Z5: Rank AR | AA5: Rank AE
A6: Australia | B6: 83 | C6: 146 | D6: 4.2 | E6: 3.8 | F6: =((B6-B$43)/(B$42-B$43))*60+70 -> 121.13636 | G6: ='z2(Rev)'!D5 -> 123.70492 | H6: =((D6-D$43)/(D$42-D$43))*60+70 -> 95.714286 | I6: =((E6-E$43)/(E$42-E$43))*60+70 -> 84.482759 | K6: =AVERAGE(F6:I6) -> 106.25958 | L6: =GEOMEAN(F6:I6) -> 104.91838 | M6: =TOPSIS!H4 -> 0.57908485 | N6: =_xlfn.STDEV.P(F6:I6)/AVERAGE(F6:I6) -> 0.15684723 | O6: =1-N6 -> 0.84315277 | P6: =1-N6^2 -> 0.97539895 | Q6: =1/(1+N6) -> 0.86441837 | R6: =EXP(-N6) -> 0.85483464 | T6: =$K6*O6 -> 89.59306 | U6: =$K6*P6 -> 103.64548 | V6: =$K6*Q6 -> 91.852735 | W6: =$K6*R6 -> 90.834371 | X6: =RANK(T6,T$6:T$40) -> 11 | Y6: =RANK(U6,U$6:U$40) -> 12 | Z6: =RANK(V6,V$6:V$40) -> 11 | AA6: =RANK(W6,W$6:W$40) -> 11
A7: Austria | B7: 81.9 | C7: 175 | D7: 5.5 | E7: 6.6 | F7: =((B7-B$43)/(B$42-B$43))*60+70 -> 113.63636 | G7: ='z2(Rev)'!D6 -> 118 | H7: =((D7-D$43)/(D$42-D$43))*60+70 -> 114.28571 | I7: =((E7-E$43)/(E$42-E$43))*60+70 -> 98.965517 | K7: =AVERAGE(F7:I7) -> 111.2219 | L7: =GEOMEAN(F7:I7) -> 110.97338 | M7: =TOPSIS!H5 -> 0.67519336 | N7: =_xlfn.STDEV.P(F7:I7)/AVERAGE(F7:I7) -> 0.065359654 | O7: =1-N7 -> 0.93464035 | P7: =1-N7^2 -> 0.99572812 | Q7: =1/(1+N7) -> 0.93865015 | R7: =EXP(-N7) -> 0.9367305 | T7: =$K7*O7 -> 103.95247 | U7: =$K7*P7 -> 110.74677 | V7: =$K7*Q7 -> 104.39845 | W7: =$K7*R7 -> 104.18495 | X7: =RANK(T7,T$6:T$40) -> 1 | Y7: =RANK(U7,U$6:U$40) -> 1 | Z7: =RANK(V7,V$6:V$40) -> 1 | AA7: =RANK(W7,W$6:W$40) -> 1
A8: Belgium | B8: 82.5 | C8: 184 | D8: 3.4 | E8: 5.4 | F8: =((B8-B$43)/(B$42-B$43))*60+70 -> 117.72727 | G8: ='z2(Rev)'!D7 -> 116.22951 | H8: =((D8-D$43)/(D$42-D$43))*60+70 -> 84.285714 | I8: =((E8-E$43)/(E$42-E$43))*60+70 -> 92.758621 | K8: =AVERAGE(F8:I8) -> 102.75028 | L8: =GEOMEAN(F8:I8) -> 101.70105 | M8: =TOPSIS!H6 -> 0.53706104 | N8: =_xlfn.STDEV.P(F8:I8)/AVERAGE(F8:I8) -> 0.14160239 | O8: =1-N8 -> 0.85839761 | P8: =1-N8^2 -> 0.97994876 | Q8: =1/(1+N8) -> 0.87596173 | R8: =EXP(-N8) -> 0.8679663 | T8: =$K8*O8 -> 88.200594 | U8: =$K8*P8 -> 100.69001 | V8: =$K8*Q8 -> 90.005312 | W8: =$K8*R8 -> 89.183779 | X8: =RANK(T8,T$6:T$40) -> 15 | Y8: =RANK(U8,U$6:U$40) -> 15 | Z8: =RANK(V8,V$6:V$40) -> 14 | AA8: =RANK(W8,W$6:W$40) -> 15
A9: Canada | B9: 81.7 | C9: 184 | D9: 2.7 | E9: 2.5 | F9: =((B9-B$43)/(B$42-B$43))*60+70 -> 112.27273 | G9: ='z2(Rev)'!D8 -> 116.22951 | H9: =((D9-D$43)/(D$42-D$43))*60+70 -> 74.285714 | I9: =((E9-E$43)/(E$42-E$43))*60+70 -> 77.758621 | K9: =AVERAGE(F9:I9) -> 95.136643 | L9: =GEOMEAN(F9:I9) -> 93.177517 | M9: =TOPSIS!H7 -> 0.44281967 | N9: =_xlfn.STDEV.P(F9:I9)/AVERAGE(F9:I9) -> 0.20186639 | O9: =1-N9 -> 0.79813361 | P9: =1-N9^2 -> 0.95924996 | Q9: =1/(1+N9) -> 0.83203924 | R9: =EXP(-N9) -> 0.81720411 | T9: =$K9*O9 -> 75.931752 | U9: =$K9*P9 -> 91.259821 | V9: =$K9*Q9 -> 79.15742 | W9: =$K9*R9 -> 77.746055 | X9: =RANK(T9,T$6:T$40) -> 31 | Y9: =RANK(U9,U$6:U$40) -> 27 | Z9: =RANK(V9,V$6:V$40) -> 29 | AA9: =RANK(W9,W$6:W$40) -> 29
A10: Chile | B10: 81.6 | C10: 229 | D10: 3.3 | E10: 1.9 | F10: =((B10-B$43)/(B$42-B$43))*60+70 -> 111.59091 | G10: ='z2(Rev)'!D9 -> 107.37705 | H10: =((D10-D$43)/(D$42-D$43))*60+70 -> 82.857143 | I10: =((E10-E$43)/(E$42-E$43))*60+70 -> 74.655172 | K10: =AVERAGE(F10:I10) -> 94.120068 | L10: =GEOMEAN(F10:I10) -> 92.786017 | M10: =TOPSIS!H8 -> 0.42359062 | N10: =_xlfn.STDEV.P(F10:I10)/AVERAGE(F10:I10) -> 0.16687193 | O10: =1-N10 -> 0.83312807 | P10: =1-N10^2 -> 0.97215376 | Q10: =1/(1+N10) -> 0.85699207 | R10: =EXP(-N10) -> 0.84630799 | T10: =$K10*O10 -> 78.41407 | U10: =$K10*P10 -> 91.499178 | V10: =$K10*Q10 -> 80.660153 | W10: =$K10*R10 -> 79.654566 | X10: =RANK(T10,T$6:T$40) -> 27 | Y10: =RANK(U10,U$6:U$40) -> 26 | Z10: =RANK(V10,V$6:V$40) -> 27 | AA10: =RANK(W10,W$6:W$40) -> 27
A11: Colombia | B11: 77.5 | C11: 419 | D11: 2.5 | E11: 1.9 | F11: =((B11-B$43)/(B$42-B$43))*60+70 -> 83.636364 | G11: ='z2(Rev)'!D10 -> 70 | H11: =((D11-D$43)/(D$42-D$43))*60+70 -> 71.428571 | I11: =((E11-E$43)/(E$42-E$43))*60+70 -> 74.655172 | K11: =AVERAGE(F11:I11) -> 74.930027 | L11: =GEOMEAN(F11:I11) -> 74.749151 | M11: =TOPSIS!H9 -> 0.11571829 | N11: =_xlfn.STDEV.P(F11:I11)/AVERAGE(F11:I11) -> 0.070758212 | O11: =1-N11 -> 0.92924179 | P11: =1-N11^2 -> 0.99499328 | Q11: =1/(1+N11) -> 0.93391766 | R11: =EXP(-N11) -> 0.93168714 | T11: =$K11*O11 -> 69.628112 | U11: =$K11*P11 -> 74.554873 | V11: =$K11*Q11 -> 69.978475 | W11: =$K11*R11 -> 69.811342 | X11: =RANK(T11,T$6:T$40) -> 34 | Y11: =RANK(U11,U$6:U$40) -> 34 | Z11: =RANK(V11,V$6:V$40) -> 34 | AA11: =RANK(W11,W$6:W$40) -> 34
A12: Czechia | B12: 79.9 | C12: 229 | D12: 4.2 | E12: 6.4 | F12: =((B12-B$43)/(B$42-B$43))*60+70 -> 100 | G12: ='z2(Rev)'!D11 -> 107.37705 | H12: =((D12-D$43)/(D$42-D$43))*60+70 -> 95.714286 | I12: =((E12-E$43)/(E$42-E$43))*60+70 -> 97.931034 | K12: =AVERAGE(F12:I12) -> 100.25559 | L12: =GEOMEAN(F12:I12) -> 100.16181 | M12: =TOPSIS!H10 -> 0.50417088 | N12: =_xlfn.STDEV.P(F12:I12)/AVERAGE(F12:I12) -> 0.043708232 | O12: =1-N12 -> 0.95629177 | P12: =1-N12^2 -> 0.99808959 | Q12: =1/(1+N12) -> 0.95812217 | R12: =EXP(-N12) -> 0.95723321 | T12: =$K12*O12 -> 95.873598 | U12: =$K12*P12 -> 100.06406 | V12: =$K12*Q12 -> 96.057106 | W12: =$K12*R12 -> 95.967982 | X12: =RANK(T12,T$6:T$40) -> 3 | Y12: =RANK(U12,U$6:U$40) -> 17 | Z12: =RANK(V12,V$6:V$40) -> 4 | AA12: =RANK(W12,W$6:W$40) -> 3
A13: Denmark | B13: 81.8 | C13: 175 | D13: 4.5 | E13: 2.3 | F13: =((B13-B$43)/(B$42-B$43))*60+70 -> 112.95455 | G13: ='z2(Rev)'!D12 -> 118 | H13: =((D13-D$43)/(D$42-D$43))*60+70 -> 100 | I13: =((E13-E$43)/(E$42-E$43))*60+70 -> 76.724138 | K13: =AVERAGE(F13:I13) -> 101.91967 | L13: =GEOMEAN(F13:I13) -> 100.56097 | M13: =TOPSIS!H11 -> 0.52491944 | N13: =_xlfn.STDEV.P(F13:I13)/AVERAGE(F13:I13) -> 0.15659077 | O13: =1-N13 -> 0.84340923 | P13: =1-N13^2 -> 0.97547933 | Q13: =1/(1+N13) -> 0.86461005 | R13: =EXP(-N13) -> 0.8550539 | T13: =$K13*O13 -> 85.959992 | U13: =$K13*P13 -> 99.420532 | V13: =$K13*Q13 -> 88.120772 | W13: =$K13*R13 -> 87.146812 | X13: =RANK(T13,T$6:T$40) -> 18 | Y13: =RANK(U13,U$6:U$40) -> 18 | Z13: =RANK(V13,V$6:V$40) -> 19 | AA13: =RANK(W13,W$6:W$40) -> 19
A14: Estonia | B14: 79.1 | C14: 323 | D14: 3.5 | E14: 4.1 | F14: =((B14-B$43)/(B$42-B$43))*60+70 -> 94.545455 | G14: ='z2(Rev)'!D13 -> 88.885246 | H14: =((D14-D$43)/(D$42-D$43))*60+70 -> 85.714286 | I14: =((E14-E$43)/(E$42-E$43))*60+70 -> 86.034483 | K14: =AVERAGE(F14:I14) -> 88.794867 | L14: =GEOMEAN(F14:I14) -> 88.725616 | M14: =TOPSIS!H12 -> 0.31621759 | N14: =_xlfn.STDEV.P(F14:I14)/AVERAGE(F14:I14) -> 0.039891311 | O14: =1-N14 -> 0.96010869 | P14: =1-N14^2 -> 0.99840868 | Q14: =1/(1+N14) -> 0.96163896 | R14: =EXP(-N14) -> 0.96089387 | T14: =$K14*O14 -> 85.252724 | U14: =$K14*P14 -> 88.653566 | V14: =$K14*Q14 -> 85.388604 | W14: =$K14*R14 -> 85.322444 | X14: =RANK(T14,T$6:T$40) -> 21 | Y14: =RANK(U14,U$6:U$40) -> 29 | Z14: =RANK(V14,V$6:V$40) -> 24 | AA14: =RANK(W14,W$6:W$40) -> 22
A15: Finland | B15: 81.6 | C15: 191 | D15: 2.9 | E15: 2.6 | F15: =((B15-B$43)/(B$42-B$43))*60+70 -> 111.59091 | G15: ='z2(Rev)'!D14 -> 114.85246 | H15: =((D15-D$43)/(D$42-D$43))*60+70 -> 77.142857 | I15: =((E15-E$43)/(E$42-E$43))*60+70 -> 78.275862 | K15: =AVERAGE(F15:I15) -> 95.465522 | L15: =GEOMEAN(F15:I15) -> 93.793593 | M15: =TOPSIS!H13 -> 0.4443482 | N15: =_xlfn.STDEV.P(F15:I15)/AVERAGE(F15:I15) -> 0.18643459 | O15: =1-N15 -> 0.81356541 | P15: =1-N15^2 -> 0.96524215 | Q15: =1/(1+N15) -> 0.84286147 | R15: =EXP(-N15) -> 0.82991285 | T15: =$K15*O15 -> 77.667447 | U15: =$K15*P15 -> 92.147345 | V15: =$K15*Q15 -> 80.46421 | W15: =$K15*R15 -> 79.228063 | X15: =RANK(T15,T$6:T$40) -> 28 | Y15: =RANK(U15,U$6:U$40) -> 23 | Z15: =RANK(V15,V$6:V$40) -> 28 | AA15: =RANK(W15,W$6:W$40) -> 28
A16: France | B16: 83 | C16: 162 | D16: 3.9 | E16: 5.4 | F16: =((B16-B$43)/(B$42-B$43))*60+70 -> 121.13636 | G16: ='z2(Rev)'!D15 -> 120.55738 | H16: =((D16-D$43)/(D$42-D$43))*60+70 -> 91.428571 | I16: =((E16-E$43)/(E$42-E$43))*60+70 -> 92.758621 | K16: =AVERAGE(F16:I16) -> 106.47023 | L16: =GEOMEAN(F16:I16) -> 105.49361 | M16: =TOPSIS!H14 -> 0.58704163 | N16: =_xlfn.STDEV.P(F16:I16)/AVERAGE(F16:I16) -> 0.13511553 | O16: =1-N16 -> 0.86488447 | P16: =1-N16^2 -> 0.98174379 | Q16: =1/(1+N16) -> 0.8809676 | R16: =EXP(-N16) -> 0.87361498 | T16: =$K16*O16 -> 92.084451 | U16: =$K16*P16 -> 104.52649 | V16: =$K16*Q16 -> 93.796825 | W16: =$K16*R16 -> 93.01399 | X16: =RANK(T16,T$6:T$40) -> 8 | Y16: =RANK(U16,U$6:U$40) -> 9 | Z16: =RANK(V16,V$6:V$40) -> 10 | AA16: =RANK(W16,W$6:W$40) -> 8
A17: Germany | B17: 81.1 | C17: 195 | D17: 4.7 | E17: 7.7 | F17: =((B17-B$43)/(B$42-B$43))*60+70 -> 108.18182 | G17: ='z2(Rev)'!D16 -> 114.06557 | H17: =((D17-D$43)/(D$42-D$43))*60+70 -> 102.85714 | I17: =((E17-E$43)/(E$42-E$43))*60+70 -> 104.65517 | K17: =AVERAGE(F17:I17) -> 107.43993 | L17: =GEOMEAN(F17:I17) -> 107.35592 | M17: =TOPSIS!H15 -> 0.62137256 | N17: =_xlfn.STDEV.P(F17:I17)/AVERAGE(F17:I17) -> 0.039817934 | O17: =1-N17 -> 0.96018207 | P17: =1-N17^2 -> 0.99841453 | Q17: =1/(1+N17) -> 0.96170682 | R17: =EXP(-N17) -> 0.96096438 | T17: =$K17*O17 -> 103.16189 | U17: =$K17*P17 -> 107.26958 | V17: =$K17*Q17 -> 103.32571 | W17: =$K17*R17 -> 103.24594 | X17: =RANK(T17,T$6:T$40) -> 2 | Y17: =RANK(U17,U$6:U$40) -> 7 | Z17: =RANK(V17,V$6:V$40) -> 2 | AA17: =RANK(W17,W$6:W$40) -> 2
... A40: USA | B40: 78.4 | C40: 312 | D40: 2.7 | E40: 2.8 | F40: =((B40-B$43)/(B$42-B$43))*60+70 -> 89.772727 | G40: ='z2(Rev)'!D39 -> 91.04918 | H40: =((D40-D$43)/(D$42-D$43))*60+70 -> 74.285714 | I40: =((E40-E$43)/(E$42-E$43))*60+70 -> 79.310345 | K40: =AVERAGE(F40:I40) -> 83.604492 | L40: =GEOMEAN(F40:I40) -> 83.303625 | M40: =TOPSIS!H38 -> 0.24613918 | N40: =_xlfn.STDEV.P(F40:I40)/AVERAGE(F40:I40) -> 0.084312851 | O40: =1-N40 -> 0.91568715 | P40: =1-N40^2 -> 0.99289134 | Q40: =1/(1+N40) -> 0.92224306 | R40: =EXP(-N40) -> 0.91914366 | T40: =$K40*O40 -> 76.555559 | U40: =$K40*P40 -> 83.010176 | V40: =$K40*Q40 -> 77.103662 | W40: =$K40*R40 -> 76.844538 | X40: =RANK(T40,T$6:T$40) -> 29 | Y40: =RANK(U40,U$6:U$40) -> 31 | Z40: =RANK(V40,V$6:V$40) -> 30 | AA40: =RANK(W40,W$6:W$40) -> 30
A42: Max | B42: =MAX(B6:B40) -> 84.3 | D42: =MAX(D6:D40) -> 6.6 | E42: =MAX(E6:E40) -> 12.6 | N42: mean | O42: =AVERAGE(O6:O40) -> 0.86921341 | P42: =AVERAGE(P6:P40) -> 0.97962875 | Q42: =AVERAGE(Q6:Q40) -> 0.88666979 | R42: =AVERAGE(R6:R40) -> 0.87885267 | S42: mean | T42: =AVERAGE(T6:T40) -> 85.513953 | U42: =AVERAGE(U6:U40) -> 96.688533 | V42: =AVERAGE(V6:V40) -> 87.308633 | W42: =AVERAGE(W6:W40) -> 86.505741
A43: Min | B43: =MIN(B6:B40) -> 75.5 | D43: =MIN(D6:D40) -> 2.4 | E43: =MIN(E6:E40) -> 1 | N43: stdev | O43: =_xlfn.STDEV.P(O6:O40) -> 0.05714998 | P43: =_xlfn.STDEV.P(P6:P40) -> 0.013552241 | Q43: =_xlfn.STDEV.P(Q6:Q40) -> 0.04613698 | R43: =_xlfn.STDEV.P(R6:R40) -> 0.050950029 | S43: stdev | T43: =_xlfn.STDEV.P(T6:T40) -> 8.4264365 | U43: =_xlfn.STDEV.P(U6:U40) -> 10.357331 | V43: =_xlfn.STDEV.P(V6:V40) -> 8.6060336 | W43: =_xlfn.STDEV.P(W6:W40) -> 8.5054618
N44: CV | O44: =O43/O42 -> 0.065749078 | P44: =P43/P42 -> 0.013834058 | Q44: =Q43/Q42 -> 0.052034004 | R44: =R43/R42 -> 0.057973345 | S44: CV | T44: =T43/T42 -> 0.098538732 | U44: =U43/U42 -> 0.10712057 | V44: =V43/V42 -> 0.098570248 | W44: =W43/W42 -> 0.098322512
N45: SE | O45: =O43/SQRT(35) -> 0.0096601098 | P45: =P43/SQRT(35) -> 0.0022907468 | Q45: =Q43/SQRT(35) -> 0.0077985729 | R45: =R43/SQRT(35) -> 0.0086121267 | S45: SE | T45: =T43/SQRT(35) -> 1.4243277 | U45: =U43/SQRT(35) -> 1.7507084 | V45: =V43/SQRT(35) -> 1.4546852 | W45: =W43/SQRT(35) -> 1.4376854
K46: Median | L46: =MEDIAN(L6:L40) -> 100.56097 | N46: Median | Q46: =MEDIAN(Q6:Q40) -> 0.87337558
N48: threshold values for typology
A49: Table S4 Geometric-mean adjusted indices for OECD health indicators | K49: Table
A50: Country | B50: Geometic Adjusted Composite Index | F50: Hierarchy | K50: TOPSIS Adjusted Composite Index | O50: Hierarchy
B51: GL | C51: GQ | D51: GR | E51: GE | F51: Rank GL | G51: Rank GQ | H51: Rank GR | I51: Rank GE | K51: TL | L51: TQ | M51: TR | N51: TE | O51: Rank TL | P51: Rank TQ | Q51: Rank TR | R51: Rank TE
A52: Australia | B52: =L6*O6 -> 88.462225 | C52: =L6*P6 -> 102.33728 | D52: =L6*Q6 -> 90.693378 | E52: =L6*R6 -> 89.687868 | F52: =RANK(B52,B$52:B$86) -> 11 | G52: =RANK(C52,C$52:C$86) -> 11 | H52: =RANK(D52,D$52:D$86) -> 11 | I52: =RANK(E52,E$52:E$86) -> 11 | K52: =M6*O6 -> 0.48825699 | L52: =M6*P6 -> 0.56483875 | M52: =M6*Q6 -> 0.50057158 | N52: =M6*R6 -> 0.49502179 | O52: =RANK(K52,K$52:K$86) -> 10 | P52: =RANK(L52,L$52:L$86) -> 12 | Q52: =RANK(M52,M$52:M$86) -> 11 | R52: =RANK(N52,N$52:N$86) -> 10
A53: Austria | B53: =L7*O7 -> 103.72019 | C53: =L7*P7 -> 110.49931 | D53: =L7*Q7 -> 104.16518 | E53: =L7*R7 -> 103.95215 | F53: =RANK(B53,B$52:B$86) -> 1 | G53: =RANK(C53,C$52:C$86) -> 1 | H53: =RANK(D53,D$52:D$86) -> 1 | I53: =RANK(E53,E$52:E$86) -> 1 | K53: =M7*O7 -> 0.63106296 | L53: =M7*P7 -> 0.67230901 | M53: =M7*Q7 -> 0.63377035 | N53: =M7*R7 -> 0.63247422 | O53: =RANK(K53,K$52:K$86) -> 1 | P53: =RANK(L53,L$52:L$86) -> 1 | Q53: =RANK(M53,M$52:M$86) -> 1 | R53: =RANK(N53,N$52:N$86) -> 1
A54: Belgium | B54: =L8*O8 -> 87.299938 | C54: =L8*P8 -> 99.661818 | D54: =L8*Q8 -> 89.086227 | E54: =L8*R8 -> 88.273084 | F54: =RANK(B54,B$52:B$86) -> 14 | G54: =RANK(C54,C$52:C$86) -> 16 | H54: =RANK(D54,D$52:D$86) -> 16 | I54: =RANK(E54,E$52:E$86) -> 15 | K54: =M8*O8 -> 0.46101191 | L54: =M8*P8 -> 0.5262923 | M54: =M8*Q8 -> 0.47044491 | N54: =M8*R8 -> 0.46615088 | O54: =RANK(K54,K$52:K$86) -> 15 | P54: =RANK(L54,L$52:L$86) -> 16 | Q54: =RANK(M54,M$52:M$86) -> 16 | R54: =RANK(N54,N$52:N$86) -> 16
A55: Canada | B55: =L9*O9 -> 74.368108 | C55: =L9*P9 -> 89.380529 | D55: =L9*Q9 -> 77.527351 | E55: =L9*R9 -> 76.14505 | F55: =RANK(B55,B$52:B$86) -> 31 | G55: =RANK(C55,C$52:C$86) -> 28 | H55: =RANK(D55,D$52:D$86) -> 29 | I55: =RANK(E55,E$52:E$86) -> 30 | K55: =M9*O9 -> 0.35342927 | L55: =M9*P9 -> 0.42477475 | M55: =M9*Q9 -> 0.36844335 | N55: =M9*R9 -> 0.36187406 | O55: =RANK(K55,K$52:K$86) -> 25 | P55: =RANK(L55,L$52:L$86) -> 23 | Q55: =RANK(M55,M$52:M$86) -> 23 | R55: =RANK(N55,N$52:N$86) -> 24
A56: Chile | B56: =L10*O10 -> 77.302635 | C56: =L10*P10 -> 90.202275 | D56: =L10*Q10 -> 79.516882 | E56: =L10*R10 -> 78.525548 | F56: =RANK(B56,B$52:B$86) -> 27 | G56: =RANK(C56,C$52:C$86) -> 26 | H56: =RANK(D56,D$52:D$86) -> 27 | I56: =RANK(E56,E$52:E$86) -> 27 | K56: =M10*O10 -> 0.35290523 | L56: =M10*P10 -> 0.41179521 | M56: =M10*Q10 -> 0.3630138 | N56: =M10*R10 -> 0.35848812 | O56: =RANK(K56,K$52:K$86) -> 26 | P56: =RANK(L56,L$52:L$86) -> 24 | Q56: =RANK(M56,M$52:M$86) -> 25 | R56: =RANK(N56,N$52:N$86) -> 26
A57: Colombia | B57: =L11*O11 -> 69.460034 | C57: =L11*P11 -> 74.374902 | D57: =L11*Q11 -> 69.809552 | E57: =L11*R11 -> 69.642822 | F57: =RANK(B57,B$52:B$86) -> 34 | G57: =RANK(C57,C$52:C$86) -> 34 | H57: =RANK(D57,D$52:D$86) -> 34 | I57: =RANK(E57,E$52:E$86) -> 34 | K57: =M11*O11 -> 0.10753027 | L57: =M11*P11 -> 0.11513892 | M57: =M11*Q11 -> 0.10807136 | N57: =M11*R11 -> 0.10781324 | O57: =RANK(K57,K$52:K$86) -> 34 | P57: =RANK(L57,L$52:L$86) -> 34 | Q57: =RANK(M57,M$52:M$86) -> 34 | R57: =RANK(N57,N$52:N$86) -> 34
A58: Czechia | B58: =L12*O12 -> 95.78391 | C58: =L12*P12 -> 99.970455 | D58: =L12*Q12 -> 95.967246 | E58: =L12*R12 -> 95.878206 | F58: =RANK(B58,B$52:B$86) -> 3 | G58: =RANK(C58,C$52:C$86) -> 14 | H58: =RANK(D58,D$52:D$86) -> 3 | I58: =RANK(E58,E$52:E$86) -> 3 | K58: =M12*O12 -> 0.48213446 | L58: =M12*P12 -> 0.50320771 | M58: =M12*Q12 -> 0.4830573 | N58: =M12*R12 -> 0.48260911 | O58: =RANK(K58,K$52:K$86) -> 12 | P58: =RANK(L58,L$52:L$86) -> 19 | Q58: =RANK(M58,M$52:M$86) -> 13 | R58: =RANK(N58,N$52:N$86) -> 13
A59: Denmark | B59: =L13*O13 -> 84.814047 | C59: =L13*P13 -> 98.095143 | D59: =L13*Q13 -> 86.946021 | E59: =L13*R13 -> 85.985046 | F59: =RANK(B59,B$52:B$86) -> 20 | G59: =RANK(C59,C$52:C$86) -> 17 | H59: =RANK(D59,D$52:D$86) -> 18 | I59: =RANK(E59,E$52:E$86) -> 18 | K59: =M13*O13 -> 0.4427219 | L59: =M13*P13 -> 0.51204806 | M59: =M13*Q13 -> 0.45385062 | N59: =M13*R13 -> 0.44883441 | O59: =RANK(K59,K$52:K$86) -> 17 | P59: =RANK(L59,L$52:L$86) -> 18 | Q59: =RANK(M59,M$52:M$86) -> 18 | R59: =RANK(N59,N$52:N$86) -> 17
A60: Estonia | B60: =L14*O14 -> 85.186235 | C60: =L14*P14 -> 88.584426 | D60: =L14*Q14 -> 85.322009 | E60: =L14*R14 -> 85.255901 | F60: =RANK(B60,B$52:B$86) -> 18 | G60: =RANK(C60,C$52:C$86) -> 29 | H60: =RANK(D60,D$52:D$86) -> 22 | I60: =RANK(E60,E$52:E$86) -> 21 | K60: =M14*O14 -> 0.30360325 | L60: =M14*P14 -> 0.31571439 | M60: =M14*Q14 -> 0.30408715 | N60: =M14*R14 -> 0.30385154 | O60: =RANK(K60,K$52:K$86) -> 29 | P60: =RANK(L60,L$52:L$86) -> 29 | Q60: =RANK(M60,M$52:M$86) -> 29 | R60: =RANK(N60,N$52:N$86) -> 29
A61: Finland | B61: =L15*O15 -> 76.307223 | C61: =L15*P15 -> 90.533529 | D61: =L15*Q15 -> 79.055006 | E61: =L15*R15 -> 77.840508 | F61: =RANK(B61,B$52:B$86) -> 28 | G61: =RANK(C61,C$52:C$86) -> 25 | H61: =RANK(D61,D$52:D$86) -> 28 | I61: =RANK(E61,E$52:E$86) -> 28 | K61: =M15*O15 -> 0.36150633 | L61: =M15*P15 -> 0.42890361 | M61: =M15*Q15 -> 0.37452398 | N61: =M15*R15 -> 0.36877028 | O61: =RANK(K61,K$52:K$86) -> 22 | P61: =RANK(L61,L$52:L$86) -> 22 | Q61: =RANK(M61,M$52:M$86) -> 22 | R61: =RANK(N61,N$52:N$86) -> 22
A62: France | B62: =L16*O16 -> 91.239781 | C62: =L16*P16 -> 103.56769 | D62: =L16*Q16 -> 92.936448 | E62: =L16*R16 -> 92.160793 | F62: =RANK(B62,B$52:B$86) -> 7 | G62: =RANK(C62,C$52:C$86) -> 9 | H62: =RANK(D62,D$52:D$86) -> 8 | I62: =RANK(E62,E$52:E$86) -> 8 | K62: =M16*O16 -> 0.50772319 | L62: =M16*P16 -> 0.57632448 | M62: =M16*Q16 -> 0.51716466 | N62: =M16*R16 -> 0.51284836 | O62: =RANK(K62,K$52:K$86) -> 7 | P62: =RANK(L62,L$52:L$86) -> 9 | Q62: =RANK(M62,M$52:M$86) -> 9 | R62: =RANK(N62,N$52:N$86) -> 9
A63: Germany | B63: =L17*O17 -> 103.08123 | C63: =L17*P17 -> 107.18571 | D63: =L17*Q17 -> 103.24492 | E63: =L17*R17 -> 103.16522 | F63: =RANK(B63,B$52:B$86) -> 2 | G63: =RANK(C63,C$52:C$86) -> 3 | H63: =RANK(D63,D$52:D$86) -> 2 | I63: =RANK(E63,E$52:E$86) -> 2 | K63: =M17*O17 -> 0.59663079 | L63: =M17*P17 -> 0.62038739 | M63: =M17*Q17 -> 0.59757823 | N63: =M17*R17 -> 0.5971169 | O63: =RANK(K63,K$52:K$86) -> 2 | P63: =RANK(L63,L$52:L$86) -> 3 | Q63: =RANK(M63,M$52:M$86) -> 2 | R63: =RANK(N63,N$52:N$86) -> 2
... A86: USA | B86: =L40*O40 -> 76.280059 | C86: =L40*P40 -> 82.711448 | D86: =L40*Q40 -> 76.82619 | E86: =L40*R40 -> 76.567998 | F86: =RANK(B86,B$52:B$86) -> 29 | G86: =RANK(C86,C$52:C$86) -> 31 | H86: =RANK(D86,D$52:D$86) -> 30 | I86: =RANK(E86,E$52:E$86) -> 29 | K86: =M40*O40 -> 0.22538648 | L86: =M40*P40 -> 0.24438946 | M86: =M40*Q40 -> 0.22700015 | N86: =M40*R40 -> 0.22623727 | O86: =RANK(K86,K$52:K$86) -> 31 | P86: =RANK(L86,L$52:L$86) -> 31 | Q86: =RANK(M86,M$52:M$86) -> 31 | R86: =RANK(N86,N$52:N$86) -> 31
A88: Mean | B88: =AVERAGE(B52:B86) -> 84.592858 | C88: =AVERAGE(C52:C86) -> 95.611751 | D88: =AVERAGE(D52:D86) -> 86.359256 | E88: =AVERAGE(E52:E86) -> 85.568916 | J88: Mean | K88: =AVERAGE(K52:K86) -> 0.4035552 | L88: =AVERAGE(L52:L86) -> 0.45923422 | M88: =AVERAGE(M52:M86) -> 0.41273677 | N88: =AVERAGE(N52:N86) -> 0.40863528
...

Sheet TOPSIS
B2: Normalized matrix
B3: z1 | C3: z2(Rev) | D3: z3 | E3: z4 | F3: D+ | G3: D- | H3: TOPSIS
A4: Australia | B4: =Tables!F6 -> 121.13636 | C4: =Tables!G6 -> 123.70492 | D4: =Tables!H6 -> 95.714286 | E4: =Tables!I6 -> 84.482759 | F4: =SQRT(SUMXMY2(B4:E4,B$40:E$40)) -> 58.013116 | G4: =SQRT(SUMXMY2(B4:E4,B$41:E$41)) -> 79.813036 | H4: =G4/(G4+F4) -> 0.57908485
A5: Austria | B5: =Tables!F7 -> 113.63636 | C5: =Tables!G7 -> 118 | D5: =Tables!H7 -> 114.28571 | E5: =Tables!I7 -> 98.965517 | F5: =SQRT(SUMXMY2(B5:E5,B$40:E$40)) -> 40.272155 | G5: =SQRT(SUMXMY2(B5:E5,B$41:E$41)) -> 83.715936 | H5: =G5/(G5+F5) -> 0.67519336
A6: Belgium | B6: =Tables!F8 -> 117.72727 | C6: =Tables!G8 -> 116.22951 | D6: =Tables!H8 -> 84.285714 | E6: =Tables!I8 -> 92.758621 | F6: =SQRT(SUMXMY2(B6:E6,B$40:E$40)) -> 61.781571 | G6: =SQRT(SUMXMY2(B6:E6,B$41:E$41)) -> 71.673541 | H6: =G6/(G6+F6) -> 0.53706104
A7: Canada | B7: =Tables!F9 -> 112.27273 | C7: =Tables!G9 -> 116.22951 | D7: =Tables!H9 -> 74.285714 | E7: =Tables!I9 -> 77.758621 | F7: =SQRT(SUMXMY2(B7:E7,B$40:E$40)) -> 79.606068 | G7: =SQRT(SUMXMY2(B7:E7,B$41:E$41)) -> 63.267009 | H7: =G7/(G7+F7) -> 0.44281967
A8: Chile | B8: =Tables!F10 -> 111.59091 | C8: =Tables!G10 -> 107.37705 | D8: =Tables!H10 -> 82.857143 | E8: =Tables!I10 -> 74.655172 | F8: =SQRT(SUMXMY2(B8:E8,B$40:E$40)) -> 78.333846 | G8: =SQRT(SUMXMY2(B8:E8,B$41:E$41)) -> 57.565826 | H8: =G8/(G8+F8) -> 0.42359062
A9: Colombia | B9: =Tables!F11 -> 83.636364 | C9: =Tables!G11 -> 70 | D9: =Tables!H11 -> 71.428571 | E9: =Tables!I11 -> 74.655172 | F9: =SQRT(SUMXMY2(B9:E9,B$40:E$40)) -> 110.64922 | G9: =SQRT(SUMXMY2(B9:E9,B$41:E$41)) -> 14.479705 | H9: =G9/(G9+F9) -> 0.11571829
A10: Czechia | B10: =Tables!F12 -> 100 | C10: =Tables!G12 -> 107.37705 | D10: =Tables!H12 -> 95.714286 | E10: =Tables!I12 -> 97.931034 | F10: =SQRT(SUMXMY2(B10:E10,B$40:E$40)) -> 60.130913 | G10: =SQRT(SUMXMY2(B10:E10,B$41:E$41)) -> 61.142546 | H10: =G10/(G10+F10) -> 0.50417088
A11: Denmark | B11: =Tables!F13 -> 112.95455 | C11: =Tables!G13 -> 118 | D11: =Tables!H13 -> 100 | E11: =Tables!I13 -> 76.724138 | F11: =SQRT(SUMXMY2(B11:E11,B$40:E$40)) -> 64.597717 | G11: =SQRT(SUMXMY2(B11:E11,B$41:E$41)) -> 71.374414 | H11: =G11/(G11+F11) -> 0.52491944
A12: Estonia | B12: =Tables!F14 -> 94.545455 | C12: =Tables!G14 -> 88.885246 | D12: =Tables!H14 -> 85.714286 | E12: =Tables!I14 -> 86.034483 | F12: =SQRT(SUMXMY2(B12:E12,B$40:E$40)) -> 82.714201 | G12: =SQRT(SUMXMY2(B12:E12,B$41:E$41)) -> 38.251474 | H12: =G12/(G12+F12) -> 0.31621759
A13: Finland | B13: =Tables!F15 -> 111.59091 | C13: =Tables!G15 -> 114.85246 | D13: =Tables!H15 -> 77.142857 | E13: =Tables!I15 -> 78.275862 | F13: =SQRT(SUMXMY2(B13:E13,B$40:E$40)) -> 77.702037 | G13: =SQRT(SUMXMY2(B13:E13,B$41:E$41)) -> 62.137405 | H13: =G13/(G13+F13) -> 0.4443482
A14: France | B14: =Tables!F16 -> 121.13636 | C14: =Tables!G16 -> 120.55738 | D14: =Tables!H16 -> 91.428571 | E14: =Tables!I16 -> 92.758621 | F14: =SQRT(SUMXMY2(B14:E14,B$40:E$40)) -> 55.157979 | G14: =SQRT(SUMXMY2(B14:E14,B$41:E$41)) -> 78.409914 | H14: =G14/(G14+F14) -> 0.58704163
A15: Germany | B15: =Tables!F17 -> 108.18182 | C15: =Tables!G17 -> 114.06557 | D15: =Tables!H17 -> 102.85714 | E15: =Tables!I17 -> 104.65517 | F15: =SQRT(SUMXMY2(B15:E15,B$40:E$40)) -> 45.92422 | G15: =SQRT(SUMXMY2(B15:E15,B$41:E$41)) -> 75.367094 | H15: =G15/(G15+F15) -> 0.62137256
... A38: USA | B38: =Tables!F40 -> 89.772727 | C38: =Tables!G40 -> 91.04918 | D38: =Tables!H40 -> 74.285714 | E38: =Tables!I40 -> 79.310345 | F38: =SQRT(SUMXMY2(B38:E38,B$40:E$40)) -> 93.855861 | G38: =SQRT(SUMXMY2(B38:E38,B$41:E$41)) -> 30.644389 | H38: =G38/(G38+F38) -> 0.24613918
A40: Max | B40: =MAX(B4:B38) -> 130 | C40: =MAX(C4:C38) -> 130 | D40: =MAX(D4:D38) -> 130 | E40: =MAX(E4:E38) -> 130 | F40: V+ | G40: Ideal point
A41: Min | B41: =MIN(B4:B38) -> 70 | C41: =MIN(C4:C38) -> 70 | D41: =MIN(D4:D38) -> 70 | E41: =MIN(E4:E38) -> 70 | F41: V- | G41: Anti-ideal point

Sheet z2(Rev)
A3: Country | B3: x2 | C3: x2(Rev) | D3: z2
B4: Mortality (cost) | C4: Mortality (Reversal) | D4: Mortality (Reversal) 70 to 130
A5: Australia | B5: 146 | C5: =(B$41-B5)+B$42 -> 387 | D5: =((C5-C$42)/(C$41-C$42))*60+70 -> 123.70492
A6: Austria | B6: 175 | C6: =(B$41-B6)+B$42 -> 358 | D6: =((C6-C$42)/(C$41-C$42))*60+70 -> 118
A7: Belgium | B7: 184 | C7: =(B$41-B7)+B$42 -> 349 | D7: =((C7-C$42)/(C$41-C$42))*60+70 -> 116.22951
A8: Canada | B8: 184 | C8: =(B$41-B8)+B$42 -> 349 | D8: =((C8-C$42)/(C$41-C$42))*60+70 -> 116.22951
A9: Chile | B9: 229 | C9: =(B$41-B9)+B$42 -> 304 | D9: =((C9-C$42)/(C$41-C$42))*60+70 -> 107.37705
A10: Colombia | B10: 419 | C10: =(B$41-B10)+B$42 -> 114 | D10: =((C10-C$42)/(C$41-C$42))*60+70 -> 70
A11: Czechia | B11: 229 | C11: =(B$41-B11)+B$42 -> 304 | D11: =((C11-C$42)/(C$41-C$42))*60+70 -> 107.37705
A12: Denmark | B12: 175 | C12: =(B$41-B12)+B$42 -> 358 | D12: =((C12-C$42)/(C$41-C$42))*60+70 -> 118
A13: Estonia | B13: 323 | C13: =(B$41-B13)+B$42 -> 210 | D13: =((C13-C$42)/(C$41-C$42))*60+70 -> 88.885246
A14: Finland | B14: 191 | C14: =(B$41-B14)+B$42 -> 342 | D14: =((C14-C$42)/(C$41-C$42))*60+70 -> 114.85246
A15: France | B15: 162 | C15: =(B$41-B15)+B$42 -> 371 | D15: =((C15-C$42)/(C$41-C$42))*60+70 -> 120.55738
A16: Germany | B16: 195 | C16: =(B$41-B16)+B$42 -> 338 | D16: =((C16-C$42)/(C$41-C$42))*60+70 -> 114.06557
... A39: USA | B39: 312 | C39: =(B$41-B39)+B$42 -> 221 | D39: =((C39-C$42)/(C$41-C$42))*60+70 -> 91.04918
A41: Max | B41: =MAX(B5:B39) -> 419 | C41: =MAX(C5:C39) -> 419
A42: Min | B42: =MIN(B5:B39) -> 114 | C42: =MIN(C5:C39) -> 114
